2018-11-19 10:26:25.278581: I tensorflow/core/common_runtime/gpu/gpu_device.cc:1405] Found device 0 with properties: 
name: Tesla K20Xm major: 3 minor: 5 memoryClockRate(GHz): 0.732
pciBusID: 0000:08:00.0
totalMemory: 5.57GiB freeMemory: 5.49GiB
2018-11-19 10:26:25.278650: I tensorflow/core/common_runtime/gpu/gpu_device.cc:1484] Adding visible gpu devices: 0
2018-11-19 10:26:25.681927: I tensorflow/core/common_runtime/gpu/gpu_device.cc:965] Device interconnect StreamExecutor with strength 1 edge matrix:
2018-11-19 10:26:25.681986: I tensorflow/core/common_runtime/gpu/gpu_device.cc:971]      0 
2018-11-19 10:26:25.681998: I tensorflow/core/common_runtime/gpu/gpu_device.cc:984] 0:   N 
2018-11-19 10:26:25.682279: I tensorflow/core/common_runtime/gpu/gpu_device.cc:1097] Created TensorFlow device (/job:localhost/replica:0/task:0/device:GPU:0 with 5278 MB memory) -> physical GPU (device: 0, name: Tesla K20Xm, pci bus id: 0000:08:00.0, compute capability: 3.5)
Using TensorFlow backend.
2018-11-20 11:29:28.523637: E tensorflow/stream_executor/cuda/cuda_driver.cc:397] failed call to cuInit: CUDA_ERROR_NO_DEVICE
2018-11-20 11:29:28.523852: I tensorflow/stream_executor/cuda/cuda_diagnostics.cc:163] retrieving CUDA diagnostic information for host: node03
2018-11-20 11:29:28.523883: I tensorflow/stream_executor/cuda/cuda_diagnostics.cc:170] hostname: node03
2018-11-20 11:29:28.524214: I tensorflow/stream_executor/cuda/cuda_diagnostics.cc:194] libcuda reported version is: 384.81.0
2018-11-20 11:29:28.524588: I tensorflow/stream_executor/cuda/cuda_diagnostics.cc:198] kernel reported version is: 384.81.0
2018-11-20 11:29:28.524627: I tensorflow/stream_executor/cuda/cuda_diagnostics.cc:305] kernel version seems to match DSO: 384.81.0
Using TensorFlow backend.
Exception ignored in: <bound method BaseSession.__del__ of <tensorflow.python.client.session.Session object at 0x7f63e5a4c5f8>>
Traceback (most recent call last):
  File "/home/arbint/.conda/envs/envDeepLearningWithProtoDUNE/lib/python3.5/site-packages/tensorflow/python/client/session.py", line 686, in __del__
TypeError: 'NoneType' object is not callable
